##  noexcept
### exception이 나지 않는 다는 것 
```
void func() noexcept
{
	throw 1;
}
int main() 
{
	func();
}
```
#### noexcept 에서 exception이나면 std::terminate를 호출한다.
```
void func() noexcept
{
	throw 1;
}
int main() 
{
	try{ func(); }
	catch (int e)
	{
		cout << e << endl;
	}
}
```
#### noexcept가 있어서 catch가 되지 않는다.
