##  try-catch
### throw를 사용해서 예외 처리 
```
#pragma warning(disable: 4996)
#include <iostream>
#include <cstdio>

using namespace std;

double divide(double d, double v)
{
	if (v == 0)
	{
		throw "Divided by zero";
	}
	return d / v;
}
int main()
{
	cout << divide(10, 2) << endl;
	cout << divide(10, 0) << endl;
}
```
#### throw가 실행 되면 std::terminate를 호출한다.
#### abort와 terminate의 차이점은 terminate는 우리가 바꿀 수 있다.
```
double divide(double d, double v)
{
	if (v == 0)
	{
		throw "Divided by zero";
	}
	return d / v;
}

void terminateFunc()
{
	cout << "Terminated" << endl;
	exit(123);
}
int main()
{
	std::set_terminate(terminateFunc);
	cout << divide(10, 0) << endl;
}
```
#### 만약 종료가 되는 것을 원하지 않으면 try를 사용하면 된다.
```
double divide(double d, double v)
{
	if (v == 0)
	{
		throw "Divided by zero";
	}
	return d / v;
}

int main()
{
	try
	{
		cout << divide(10, 0) << endl;
	}
	catch (const char* e)
	{
		cout << e << endl;
	}
}
```
#### catch는 throw해준 것을 받는 다는 뜻이다.
#### 만약 어떤 에러가 날지 예상이 되지 않지만 무조건 받아야만 한다면 
```
double divide(double d, double v)
{
	if (v == 0)
	{
		throw "Divided by zero";
	}
	return d / v;
}

int main()
{
	try
	{
		cout << divide(10, 0) << endl;
	}
	catch (const char* e)
	{
		cout << e << endl;
	}
	catch (...)
	{
		cout << "..." << endl;
	}
}
```
#### ...을 사용해서 받을 수 있다.
#### const char 포인터를 받지만 int 타입을 throw 하면 
#### ...에서 받는다.
#### 하지만 catch (...)을 지우고 int 를 throw하면 int를 받을 catch가 없기 때문에 프로그램이 죽는다
#### class를 throw해서 자식으로 받을 수 있다
```
class Parent
{
public:
	virtual ~Parent() {}
};

class Child : public Parent
{

};

double divide(double d, double v)
{
	if (v == 0)
	{
		throw Child();
	}
	return d / v;
}

int main()
{
	try
	{
		cout << divide(10, 0) << endl;
	}
	catch (const char* e)
	{
		cout << e << endl;
	}
	catch (Parent)
	{
		cout << "parent" << endl;
	}
```
#### catch는 위에서 보기 때문에 아래의 소스에서도 parent가 호출된다. 그러므로 구체적인 catch를 더 위에 작성해 줘야 된다.
```
class Parent
{
public:
	virtual ~Parent() {}
};

class Child : public Parent
{

};

double divide(double d, double v)
{
	if (v == 0)
	{
		throw Child();
	}
	return d / v;
}

int main()
{
	try
	{
		cout << divide(10, 0) << endl;
	}
	catch (const char* e)
	{
		cout << e << endl;
	}
	catch (Parent)
	{
		cout << "parent" << endl;
	}
	catch (Child)
	{
		cout << "child" << endl;
	}
}
```
#### 참조형식으로 받아야 복사가 이뤄지지 않는다.
```
class Parent
{
public:
	virtual ~Parent() {}
};

class Child : public Parent
{

};

double divide(double d, double v)
{
	if (v == 0)
	{
		throw Child();
	}
	return d / v;
}

int main()
{
	try
	{
		cout << divide(10, 0) << endl;
	}
	catch (const char* e)
	{
		cout << e << endl;
	}
	catch (Child&)
	{
		cout << "child" << endl;
	}
	catch (Parent&)
	{
		cout << "parent" << endl;
	}
}
```
#### divide가 호출되면 스택프래임이 만들어 진다. divide를 수행하기 위한 
#### return은 divide 스택 하나만 파괴를 한다.
#### throw는 divide 하나만 파괴하지 않는다.
```
double divide(double d, double v)
{
	if (v == 0)
	{
		throw "Divided by zero";
	}
	return d / v;
}

void func1()
{
	divide(10, 0);
}

void func0()
{
	func1();
}

int main()
{
	try
	{
		func0();
	}
	catch (const char* e)
	{
		cout << e << endl;
	}
}
```
#### throw가 호출 되면 catch까지 올라오면서 스택을 파.괘.한.다.
#### 그러므로 그래서 throw를 만나면 func1 삭제 func0을 파괴하고 catch 문으로 온다.
```
double divide(double d, double v)
{
	if (v == 0)
	{
		throw "Divided by zero";
	}
	return d / v;
}

void func1()
{
	divide(10, 1);
	cout << "func1" << endl;
}

void func0()
{
	func1();
	cout << "func0" << endl;
}

int main()
{
	try
	{
		func0();
    cout << "main" << endl;
	}
	catch (const char* e)
	{
		cout << e << endl;
	}
}
```
#### 위의 소스는 cout << fun0 << endl;이 실행되지만
#### 0으로 나누어 throw를 만나게 되면 
#### cout이 실행 되지 않는다.
#### 이를 스택 되감기라고 하는 하는데 이 과정 중에 있는 스택의 선언에 되어있던 변수(자동지역변수)가 파괴가 된다.
```
#pragma warning(disable: 4996)
#include <iostream>
#include <cstdio>

using namespace std;

class Test
{
private:
	std::string msg;
public:
	Test(const std::string&msg) : msg(msg) {}
	~Test()
	{
		cout << msg << endl;
	}
};
double divide(double d, double v)
{
	Test t("divide");
	if (v == 0)
	{
		throw "Divided by zero";
	}
	return d / v;
}

void func1()
{
	Test t("func1 test");
	divide(10, 0);
	cout << "func1" << endl;
}

void func0()
{
	Test t("func0 test");
	func1();
	cout << "func0" << endl;
}

int main()
{
	try
	{
		func0();
	}
	catch (const char* e)
	{
		cout << e << endl;
	}
}
```
#### 위의 소스를 실행해 보면 스택 뒤감는 순서대로 클래스가 파괴됨을 확인할 수 있다.

#### func1에서 divide의 에러를 잡을 수 있다.
```
double divide(double d, double v)
{
	if (v == 0)
	{
		throw "Divided by zero";
	}
	return d / v;
}

void func1()
{
	try {
		divide(10, 0);
	}
	catch (const char* e)
	{
		cout << "func1 handled exception" << endl;
	}
}

void func0()
{
	func1();

}

int main()
{
	try
	{
		func0();
		cout << "main" << endl;
	}
	catch (const char* e)
	{
		cout << e << endl;
	}
}

```
#### func1에서 exception을 핸들링 했기때문에 main에서 핸들링 할 필요가 없다.
#### func1에서 throw를 한번 더 해주면 main또 해줄 수 있다.

#### main함수 자체가 try로 감싸줘 있는데 이럴 떄는 
```
int main() try
{
	func0();
	cout << "main" << endl;
}
catch (const char* e)
{
	cout << e << endl;
}
```
#### 함수 뒤에 붙여서 감싸줄 수 있다.
#### 하지만 try block은 좁으면 좁을 수록 좋다.
#### std::exception을 사용해서 exception을 보낼 수 있다.

#### 그리고 catch보다는 extepction& e를 사용하면 좋다.
